异常处理try 可以throw多个异常 之后的catch也可捕获多个异常（捕获第一个）    
try 写正常代码 正常运行后 return   
throw并catch异常 后try之后不执行  catch后 执行catch最后括号之后的内容
```
private Coffee readCoffee() throws IOException {
		/* my code */
		stdOut.println("请输入 id ; name ; taste; cost ");
		String s1 = (stdIn.readLine());

		try {
			StringTokenizer token1 = new StringTokenizer(s1, "_");
			if (token1.countTokens() < 4) {
				throw new IOException("输入个数小于4个");
			}

			if (token1.countTokens() > 4)
				throw new IOException("输入个数大于4个");

			int id = Integer.parseInt(token1.nextToken());

			if (id <= MIN_NUMBER || id > MAX_NUMBER)
				throw new IOException(id + " id out of range");

			String name = token1.nextToken();
			String taste = token1.nextToken();

			double cost = Double.parseDouble(token1.nextToken());
			if (cost < MIN_COST || cost > MAX_COST)
				throw new IOException(cost + " cost out of range");
			Coffee legalCoffee = new Coffee(id, name, taste, cost);
			stdOut.println("add coffee success" + "\n");
			return legalCoffee;

		} catch (NumberFormatException err) {
			stdErr.println(err);
			stdErr.println("input  is not valid");
		} catch (IOException err2) {
			stdErr.println(err2);
		}

		stdOut.println("add coffee failed");
		stdErr.flush();
		stdOut.println("\n" + "请再次输入");
		return readCoffee(); // 防止返回空对象

	}
}
```
